{"name": "test_create_duplicate_courier", "status": "failed", "statusDetails": {"message": "AssertionError: Неверное сообщение об ошибке - Этот логин уже используется. Попробуйте другой.", "trace": "self = <tests.test_courier_creation.TestCourierCreation object at 0x0000026D43ECC650>\n\n    @allure.description('Сохдание курьера с уже существующими данными')\n    def test_create_duplicate_courier(self):\n        new_courier = UserGenerator.register_new_courier_and_return_login_password()\n        payload = {'login': new_courier[0],\n                   'password': new_courier[1],\n                   'first_name': new_courier[2]\n                   }\n        response = requests.post(ApiUrl.CREATE_COURIER_API_URL, data=payload)\n        Assertions.assert_code_status(response, 409)\n>       Assertions.assert_json_value_by_name(response,\n                                             'message',\n                                             'Этот логин уже используется',\n                                             f'Неверное сообщение об ошибке - {response.json()['message']}'\n                                             )\n\ntests\\test_courier_creation.py:38: \n_ _ _ _ _ _ _ _ _ _ _ _ _ _ _ _ _ _ _ _ _ _ _ _ _ _ _ _ _ _ _ _ _ _ _ _ _ _ _ _ _ _ _ _ _ _ _ _ _ _ _ _ _ _ _ _ _ _ _ _ _ _ _ _ _ _ _ _ _ _ _ _ _ _ _ _ _ _ _ _ _ _ _ _ _ _ _ _ _ _\n\nresponse = <Response [409]>, name = 'message', expected_value = 'Этот логин уже используется'\nerror_message = 'Неверное сообщение об ошибке - Этот логин уже используется. Попробуйте другой.'\n\n    @staticmethod\n    def assert_json_value_by_name(response: Response, name, expected_value, error_message):\n        try:\n            response_as_dict = response.json()\n        except json.JSONDecodeError:\n            assert False, f\"Response is not in JSON format. Response text is '{response.text}'\"\n    \n        assert name in response_as_dict, f\"Response JSON does not have key '{name}'\"\n>       assert response_as_dict[name] == expected_value, error_message\nE       AssertionError: Неверное сообщение об ошибке - Этот логин уже используется. Попробуйте другой.\n\nhelpful_classes\\assertions.py:14: AssertionError"}, "description": "Сохдание курьера с уже существующими данными", "start": 1710632391248, "stop": 1710632392102, "uuid": "e5c02164-ed3c-49b2-ad4c-d9d6479cabe8", "historyId": "59837c5c08bc86d2e476e34fa9a8709d", "testCaseId": "59837c5c08bc86d2e476e34fa9a8709d", "fullName": "tests.test_courier_creation.TestCourierCreation#test_create_duplicate_courier", "labels": [{"name": "epic", "value": "Создание курьера"}, {"name": "parentSuite", "value": "tests"}, {"name": "suite", "value": "test_courier_creation"}, {"name": "subSuite", "value": "TestCourierCreation"}, {"name": "host", "value": "LAPTOP-IE2IJGHD"}, {"name": "thread", "value": "2840-MainThread"}, {"name": "framework", "value": "pytest"}, {"name": "language", "value": "cpython3"}, {"name": "package", "value": "tests.test_courier_creation"}]}